LAST SEEN   TYPE      REASON              OBJECT                                          MESSAGE
36m         Warning   FailedScheduling    pod/relevance-scorer-cd555d678-zt7qd            0/1 nodes are available: 1 Insufficient memory. no new claims to deallocate, preemption: 0/1 nodes are available: 1 No preemption victims found for incoming pod.
42m         Normal    Scheduled           pod/relevance-scorer-cd555d678-6z2dc            Successfully assigned fraud-buster/relevance-scorer-cd555d678-6z2dc to minikube
14m         Warning   FailedScheduling    pod/mongo-5dfcf95c47-mmwwg                      0/1 nodes are available: 1 Insufficient memory. no new claims to deallocate, preemption: 0/1 nodes are available: 1 No preemption victims found for incoming pod.
37m         Warning   FailedScheduling    pod/review-classifier-7cdcd474d8-dtr65          0/1 nodes are available: 1 Insufficient memory. no new claims to deallocate, preemption: 0/1 nodes are available: 1 No preemption victims found for incoming pod.
42m         Warning   FailedScheduling    pod/review-classifier-7cdcd474d8-dtr65          0/1 nodes are available: 1 Insufficient memory. no new claims to deallocate, preemption: 0/1 nodes are available: 1 No preemption victims found for incoming pod.
14m         Warning   FailedScheduling    pod/review-classifier-7cdcd474d8-7rzwp          0/1 nodes are available: 1 Insufficient memory. no new claims to deallocate, preemption: 0/1 nodes are available: 1 No preemption victims found for incoming pod.
41m         Warning   FailedScheduling    pod/relevance-scorer-cd555d678-zt7qd            0/1 nodes are available: 1 Insufficient memory. no new claims to deallocate, preemption: 0/1 nodes are available: 1 No preemption victims found for incoming pod.
43m         Normal    ScalingReplicaSet   deployment/review-classifier                    Scaled up replica set review-classifier-7cdcd474d8 from 1 to 2
43m         Normal    ScalingReplicaSet   deployment/relevance-scorer                     Scaled up replica set relevance-scorer-cd555d678 from 1 to 2
43m         Normal    SuccessfulRescale   horizontalpodautoscaler/relevance-scorer-hpa    New size: 2; reason: cpu resource utilization (percentage of request) above target
43m         Normal    SuccessfulRescale   horizontalpodautoscaler/review-classifier-hpa   New size: 2; reason: cpu resource utilization (percentage of request) above target
42m         Normal    SuccessfulCreate    replicaset/relevance-scorer-cd555d678           Created pod: relevance-scorer-cd555d678-6z2dc
42m         Normal    SuccessfulCreate    replicaset/review-classifier-7cdcd474d8         Created pod: review-classifier-7cdcd474d8-dtr65
42m         Normal    Pulling             pod/relevance-scorer-cd555d678-6z2dc            Pulling image "caffeinatedkong/relevance-scorer:latest"
42m         Normal    Created             pod/relevance-scorer-cd555d678-6z2dc            Created container: relevance-scorer
42m         Normal    Pulled              pod/relevance-scorer-cd555d678-6z2dc            Successfully pulled image "caffeinatedkong/relevance-scorer:latest" in 2.745s (2.746s including waiting). Image size: 898174856 bytes.
42m         Normal    Started             pod/relevance-scorer-cd555d678-6z2dc            Started container relevance-scorer
42m         Warning   Unhealthy           pod/redis-6d9c5b88d4-zrwlg                      Readiness probe failed: command timed out: "redis-cli ping" timed out after 3s
42m         Warning   Unhealthy           pod/relevance-scorer-cd555d678-6z2dc            Liveness probe failed: dial tcp 10.244.0.181:50052: connect: connection refused
42m         Warning   Unhealthy           pod/relevance-scorer-cd555d678-6z2dc            Readiness probe failed: dial tcp 10.244.0.181:50052: connect: connection refused
41m         Normal    SuccessfulRescale   horizontalpodautoscaler/relevance-scorer-hpa    New size: 3; reason: cpu resource utilization (percentage of request) above target
41m         Normal    SuccessfulCreate    replicaset/relevance-scorer-cd555d678           Created pod: relevance-scorer-cd555d678-zt7qd
41m         Normal    ScalingReplicaSet   deployment/relevance-scorer                     Scaled up replica set relevance-scorer-cd555d678 from 2 to 3
36m         Normal    SuccessfulRescale   horizontalpodautoscaler/review-classifier-hpa   New size: 1; reason: All metrics below target
36m         Normal    ScalingReplicaSet   deployment/review-classifier                    Scaled down replica set review-classifier-7cdcd474d8 from 2 to 1
36m         Normal    SuccessfulDelete    replicaset/review-classifier-7cdcd474d8         Deleted pod: review-classifier-7cdcd474d8-dtr65
35m         Normal    SuccessfulDelete    replicaset/relevance-scorer-cd555d678           Deleted pod: relevance-scorer-cd555d678-6z2dc
35m         Normal    ScalingReplicaSet   deployment/relevance-scorer                     Scaled down replica set relevance-scorer-cd555d678 from 3 to 1
35m         Normal    SuccessfulRescale   horizontalpodautoscaler/relevance-scorer-hpa    New size: 1; reason: All metrics below target
35m         Normal    SuccessfulDelete    replicaset/relevance-scorer-cd555d678           Deleted pod: relevance-scorer-cd555d678-zt7qd
35m         Normal    Killing             pod/relevance-scorer-cd555d678-6z2dc            Stopping container relevance-scorer
