LAST SEEN   TYPE      REASON                         OBJECT                                          MESSAGE
29m         Warning   FailedScheduling               pod/review-classifier-7cdcd474d8-pfk4f          0/1 nodes are available: 1 Insufficient memory. no new claims to deallocate, preemption: 0/1 nodes are available: 1 No preemption victims found for incoming pod.
40m         Warning   FailedScheduling               pod/relevance-scorer-cd555d678-dntnc            0/1 nodes are available: 1 Insufficient memory. no new claims to deallocate, preemption: 0/1 nodes are available: 1 No preemption victims found for incoming pod.
49m         Warning   FailedScheduling               pod/mongo-5dfcf95c47-mmwwg                      0/1 nodes are available: 1 Insufficient memory. no new claims to deallocate, preemption: 0/1 nodes are available: 1 No preemption victims found for incoming pod.
37m         Warning   FailedScheduling               pod/mongo-5dfcf95c47-mmwwg                      0/1 nodes are available: 1 Insufficient memory. no new claims to deallocate, preemption: 0/1 nodes are available: 1 No preemption victims found for incoming pod.
53s         Warning   FailedScheduling               pod/mongo-5dfcf95c47-mmwwg                      0/1 nodes are available: 1 Insufficient memory. no new claims to deallocate, preemption: 0/1 nodes are available: 1 No preemption victims found for incoming pod.
9m25s       Normal    Scheduled                      pod/flask-app-5886b89967-sd6nr                  Successfully assigned fraud-buster/flask-app-5886b89967-sd6nr to minikube
29m         Normal    Scheduled                      pod/relevance-scorer-cd555d678-77xm6            Successfully assigned fraud-buster/relevance-scorer-cd555d678-77xm6 to minikube
24m         Warning   FailedScheduling               pod/review-classifier-7cdcd474d8-pfk4f          0/1 nodes are available: 1 Insufficient memory. no new claims to deallocate, preemption: 0/1 nodes are available: 1 No preemption victims found for incoming pod.
41m         Warning   FailedScheduling               pod/review-classifier-7cdcd474d8-746q5          0/1 nodes are available: 1 Insufficient memory. no new claims to deallocate, preemption: 0/1 nodes are available: 1 No preemption victims found for incoming pod.
41m         Normal    Scheduled                      pod/relevance-scorer-cd555d678-xgdtx            Successfully assigned fraud-buster/relevance-scorer-cd555d678-xgdtx to minikube
23m         Warning   FailedScheduling               pod/relevance-scorer-cd555d678-lp5wf            0/1 nodes are available: 1 Insufficient memory. no new claims to deallocate, preemption: 0/1 nodes are available: 1 No preemption victims found for incoming pod.
28m         Warning   FailedScheduling               pod/relevance-scorer-cd555d678-lp5wf            0/1 nodes are available: 1 Insufficient memory. no new claims to deallocate, preemption: 0/1 nodes are available: 1 No preemption victims found for incoming pod.
35m         Warning   FailedScheduling               pod/relevance-scorer-cd555d678-dntnc            0/1 nodes are available: 1 Insufficient memory. no new claims to deallocate, preemption: 0/1 nodes are available: 1 No preemption victims found for incoming pod.
41m         Warning   FailedScheduling               pod/flask-app-5886b89967-7jzbh                  0/1 nodes are available: 1 Insufficient memory. no new claims to deallocate, preemption: 0/1 nodes are available: 1 No preemption victims found for incoming pod.
8m25s       Warning   FailedScheduling               pod/flask-app-5886b89967-994qg                  0/1 nodes are available: 1 Insufficient memory. no new claims to deallocate, preemption: 0/1 nodes are available: 1 No preemption victims found for incoming pod.
3m3s        Warning   FailedScheduling               pod/flask-app-5886b89967-994qg                  0/1 nodes are available: 1 Insufficient memory. no new claims to deallocate, preemption: 0/1 nodes are available: 1 No preemption victims found for incoming pod.
9m25s       Warning   FailedScheduling               pod/flask-app-5886b89967-c5z86                  0/1 nodes are available: 1 Insufficient memory. no new claims to deallocate, preemption: 0/1 nodes are available: 1 No preemption victims found for incoming pod.
4m3s        Warning   FailedScheduling               pod/flask-app-5886b89967-c5z86                  0/1 nodes are available: 1 Insufficient memory. no new claims to deallocate, preemption: 0/1 nodes are available: 1 No preemption victims found for incoming pod.
41m         Warning   FailedScheduling               pod/flask-app-5886b89967-h68v8                  0/1 nodes are available: 1 Insufficient memory. no new claims to deallocate, preemption: 0/1 nodes are available: 1 No preemption victims found for incoming pod.
8m25s       Warning   FailedScheduling               pod/flask-app-5886b89967-jclvb                  0/1 nodes are available: 1 Insufficient memory. no new claims to deallocate, preemption: 0/1 nodes are available: 1 No preemption victims found for incoming pod.
3m3s        Warning   FailedScheduling               pod/flask-app-5886b89967-jclvb                  0/1 nodes are available: 1 Insufficient memory. no new claims to deallocate, preemption: 0/1 nodes are available: 1 No preemption victims found for incoming pod.
8m55s       Warning   FailedScheduling               pod/flask-app-5886b89967-kttqg                  0/1 nodes are available: 1 Insufficient memory. no new claims to deallocate, preemption: 0/1 nodes are available: 1 No preemption victims found for incoming pod.
3m33s       Warning   FailedScheduling               pod/flask-app-5886b89967-kttqg                  0/1 nodes are available: 1 Insufficient memory. no new claims to deallocate, preemption: 0/1 nodes are available: 1 No preemption victims found for incoming pod.
8m25s       Warning   FailedScheduling               pod/flask-app-5886b89967-mth6m                  0/1 nodes are available: 1 Insufficient memory. no new claims to deallocate, preemption: 0/1 nodes are available: 1 No preemption victims found for incoming pod.
3m3s        Warning   FailedScheduling               pod/flask-app-5886b89967-mth6m                  0/1 nodes are available: 1 Insufficient memory. no new claims to deallocate, preemption: 0/1 nodes are available: 1 No preemption victims found for incoming pod.
53s         Warning   FailedScheduling               pod/review-classifier-7cdcd474d8-7rzwp          0/1 nodes are available: 1 Insufficient memory. no new claims to deallocate, preemption: 0/1 nodes are available: 1 No preemption victims found for incoming pod.
36m         Warning   FailedScheduling               pod/review-classifier-7cdcd474d8-746q5          0/1 nodes are available: 1 Insufficient memory. no new claims to deallocate, preemption: 0/1 nodes are available: 1 No preemption victims found for incoming pod.
49m         Warning   FailedScheduling               pod/review-classifier-7cdcd474d8-7rzwp          0/1 nodes are available: 1 Insufficient memory. no new claims to deallocate, preemption: 0/1 nodes are available: 1 No preemption victims found for incoming pod.
37m         Warning   FailedScheduling               pod/review-classifier-7cdcd474d8-7rzwp          0/1 nodes are available: 1 Insufficient memory. no new claims to deallocate, preemption: 0/1 nodes are available: 1 No preemption victims found for incoming pod.
43m         Warning   Unhealthy                      pod/scheduler-6bbf94dcc-8hz2w                   Liveness probe errored and resulted in unknown state: rpc error: code = Unknown desc = Cannot connect to the Docker daemon at unix:///var/run/docker.sock. Is the docker daemon running?
43m         Warning   Unhealthy                      pod/flask-app-5886b89967-s5sgc                  Liveness probe failed: Get "http://10.244.0.147:5000/health": dial tcp 10.244.0.147:5000: connect: connection refused
43m         Warning   Unhealthy                      pod/flask-app-5886b89967-s5sgc                  Readiness probe failed: Get "http://10.244.0.147:5000/health": dial tcp 10.244.0.147:5000: connect: connection refused
43m         Warning   Unhealthy                      pod/flask-app-5886b89967-4zgfn                  Liveness probe failed: Get "http://10.244.0.142:5000/health": dial tcp 10.244.0.142:5000: connect: connection refused
43m         Warning   Unhealthy                      pod/scraper-548b7ddb9f-jssgw                    Readiness probe failed: dial tcp 10.244.0.141:50053: connect: connection refused
43m         Warning   Unhealthy                      pod/scheduler-6bbf94dcc-8hz2w                   Readiness probe errored and resulted in unknown state: rpc error: code = Unknown desc = container not running (10dde1a1cbd305ddd0c6ff8c5c602036e61bfb62bb0749cd183e62c5cc0b2d8f)
43m         Warning   Unhealthy                      pod/redis-6d9c5b88d4-zrwlg                      Liveness probe errored and resulted in unknown state: rpc error: code = Unknown desc = container not running (4493fde325eb6b83b1fa56e5c8031f81aee38f88ef2c4cd75fba913285e42f34)
43m         Warning   Unhealthy                      pod/flask-app-5886b89967-4zgfn                  Readiness probe failed: Get "http://10.244.0.142:5000/health": dial tcp 10.244.0.142:5000: connect: connection refused
43m         Warning   Unhealthy                      pod/flask-app-5886b89967-s5sgc                  Readiness probe failed: Get "http://10.244.0.147:5000/health": context deadline exceeded (Client.Timeout exceeded while awaiting headers)
43m         Warning   Unhealthy                      pod/redis-6d9c5b88d4-zrwlg                      Readiness probe errored and resulted in unknown state: rpc error: code = Unknown desc = container not running (4493fde325eb6b83b1fa56e5c8031f81aee38f88ef2c4cd75fba913285e42f34)
43m         Warning   FailedSync                     pod/flask-app-5886b89967-s5sgc                  error determining status: rpc error: code = Unavailable desc = connection error: desc = "transport: Error while dialing: dial unix /var/run/cri-dockerd.sock: connect: connection refused"
43m         Warning   Unhealthy                      pod/relevance-scorer-cd555d678-6tmdr            Liveness probe failed: dial tcp 10.244.0.138:50052: connect: no route to host
43m         Warning   Unhealthy                      pod/scraper-548b7ddb9f-jssgw                    Liveness probe failed: dial tcp 10.244.0.141:50053: connect: no route to host
43m         Warning   Unhealthy                      pod/relevance-scorer-cd555d678-6tmdr            Readiness probe failed: dial tcp 10.244.0.138:50052: i/o timeout
43m         Warning   Unhealthy                      pod/mongo-store-7fb479c547-z4bjn                Readiness probe failed: dial tcp 10.244.0.149:50054: i/o timeout
43m         Warning   Unhealthy                      pod/mongo-store-7fb479c547-z4bjn                Liveness probe failed: dial tcp 10.244.0.149:50054: connect: no route to host
42m         Normal    Pulled                         pod/flask-app-5886b89967-s5sgc                  Successfully pulled image "caffeinatedkong/flask-app:latest" in 14.498s (14.499s including waiting). Image size: 749810154 bytes.
42m         Warning   Failed                         pod/flask-app-5886b89967-s5sgc                  Error: failed to sync configmap cache: timed out waiting for the condition
42m         Normal    Pulled                         pod/scraper-548b7ddb9f-jssgw                    Successfully pulled image "caffeinatedkong/scraper:latest" in 4.866s (18.979s including waiting). Image size: 523842750 bytes.
42m         Warning   Failed                         pod/scraper-548b7ddb9f-jssgw                    Error: failed to sync configmap cache: timed out waiting for the condition
42m         Normal    Pulled                         pod/relevance-scorer-cd555d678-6tmdr            Successfully pulled image "caffeinatedkong/relevance-scorer:latest" in 3.826s (22.804s including waiting). Image size: 898174856 bytes.
42m         Normal    Pulled                         pod/scheduler-6bbf94dcc-8hz2w                   Successfully pulled image "caffeinatedkong/scheduler:latest" in 4.846s (26.501s including waiting). Image size: 487939183 bytes.
42m         Warning   Failed                         pod/scheduler-6bbf94dcc-8hz2w                   Error: failed to sync configmap cache: timed out waiting for the condition
42m         Normal    Pulled                         pod/redis-6d9c5b88d4-zrwlg                      Successfully pulled image "redis:latest" in 3.208s (29.283s including waiting). Image size: 137229198 bytes.
42m         Normal    Pulled                         pod/review-classifier-85c4497458-ljdxf          Successfully pulled image "caffeinatedkong/review-classifier:latest" in 4.21s (30.21s including waiting). Image size: 1872336796 bytes.
42m         Normal    Pulled                         pod/mongo-store-7fb479c547-z4bjn                Successfully pulled image "caffeinatedkong/mongo-store:latest" in 4.005s (28.706s including waiting). Image size: 520025736 bytes.
42m         Normal    Pulled                         pod/flask-app-5886b89967-4zgfn                  Successfully pulled image "caffeinatedkong/flask-app:latest" in 3.427s (28.041s including waiting). Image size: 749810154 bytes.
42m         Normal    Pulled                         pod/flask-app-5886b89967-s5sgc                  Successfully pulled image "caffeinatedkong/flask-app:latest" in 3.524s (26.749s including waiting). Image size: 749810154 bytes.
42m         Normal    Pulled                         pod/scraper-548b7ddb9f-jssgw                    Successfully pulled image "caffeinatedkong/scraper:latest" in 2.621s (27.7s including waiting). Image size: 523842750 bytes.
42m         Normal    Pulled                         pod/relevance-scorer-cd555d678-6tmdr            Successfully pulled image "caffeinatedkong/relevance-scorer:latest" in 3.059s (27.458s including waiting). Image size: 898174856 bytes.
42m         Normal    Pulled                         pod/scheduler-6bbf94dcc-8hz2w                   Successfully pulled image "caffeinatedkong/scheduler:latest" in 4.175s (26.531s including waiting). Image size: 487939183 bytes.
41m         Warning   Unhealthy                      pod/relevance-scorer-cd555d678-6tmdr            Liveness probe failed: dial tcp 10.244.0.157:50052: connect: connection refused
41m         Warning   FailedGetResourceMetric        horizontalpodautoscaler/review-classifier-hpa   failed to get cpu utilization: unable to get metrics for resource cpu: no metrics returned from resource metrics API
41m         Warning   FailedGetResourceMetric        horizontalpodautoscaler/mongo-store-hpa         failed to get cpu utilization: unable to get metrics for resource cpu: no metrics returned from resource metrics API
41m         Warning   FailedGetResourceMetric        horizontalpodautoscaler/flask-app-hpa           failed to get cpu utilization: unable to get metrics for resource cpu: no metrics returned from resource metrics API
41m         Warning   FailedGetResourceMetric        horizontalpodautoscaler/flask-app-hpa           failed to get memory utilization: unable to get metrics for resource memory: no metrics returned from resource metrics API
41m         Warning   FailedComputeMetricsReplicas   horizontalpodautoscaler/flask-app-hpa           invalid metrics (2 invalid out of 2), first error is: failed to get cpu resource metric value: failed to get cpu utilization: unable to get metrics for resource cpu: no metrics returned from resource metrics API
41m         Warning   FailedGetResourceMetric        horizontalpodautoscaler/relevance-scorer-hpa    failed to get cpu utilization: unable to get metrics for resource cpu: no metrics returned from resource metrics API
41m         Warning   FailedGetResourceMetric        horizontalpodautoscaler/scraper-hpa             failed to get cpu utilization: unable to get metrics for resource cpu: no metrics returned from resource metrics API
41m         Warning   FailedComputeMetricsReplicas   horizontalpodautoscaler/review-classifier-hpa   invalid metrics (1 invalid out of 1), first error is: failed to get cpu resource metric value: failed to get cpu utilization: unable to get metrics for resource cpu: no metrics returned from resource metrics API
41m         Warning   FailedComputeMetricsReplicas   horizontalpodautoscaler/mongo-store-hpa         invalid metrics (1 invalid out of 1), first error is: failed to get cpu resource metric value: failed to get cpu utilization: unable to get metrics for resource cpu: no metrics returned from resource metrics API
41m         Warning   FailedComputeMetricsReplicas   horizontalpodautoscaler/relevance-scorer-hpa    invalid metrics (1 invalid out of 1), first error is: failed to get cpu resource metric value: failed to get cpu utilization: unable to get metrics for resource cpu: no metrics returned from resource metrics API
41m         Warning   FailedComputeMetricsReplicas   horizontalpodautoscaler/scraper-hpa             invalid metrics (1 invalid out of 1), first error is: failed to get cpu resource metric value: failed to get cpu utilization: unable to get metrics for resource cpu: no metrics returned from resource metrics API
41m         Normal    Sync                           ingress/fraud-buster-ingress                    Scheduled for sync
41m         Normal    SuccessfulRescale              horizontalpodautoscaler/relevance-scorer-hpa    New size: 2; reason: cpu resource utilization (percentage of request) above target
41m         Normal    SuccessfulCreate               replicaset/review-classifier-7cdcd474d8         Created pod: review-classifier-7cdcd474d8-746q5
41m         Normal    SuccessfulCreate               replicaset/flask-app-5886b89967                 Created pod: flask-app-5886b89967-7jzbh
41m         Normal    ScalingReplicaSet              deployment/flask-app                            Scaled up replica set flask-app-5886b89967 from 2 to 4
41m         Normal    SuccessfulCreate               replicaset/flask-app-5886b89967                 Created pod: flask-app-5886b89967-h68v8
41m         Normal    SuccessfulCreate               replicaset/relevance-scorer-cd555d678           Created pod: relevance-scorer-cd555d678-xgdtx
41m         Normal    ScalingReplicaSet              deployment/review-classifier                    Scaled up replica set review-classifier-7cdcd474d8 from 1 to 2
41m         Normal    SuccessfulRescale              horizontalpodautoscaler/flask-app-hpa           New size: 4; reason: cpu resource utilization (percentage of request) above target
41m         Normal    SuccessfulRescale              horizontalpodautoscaler/review-classifier-hpa   New size: 2; reason: cpu resource utilization (percentage of request) above target
41m         Normal    ScalingReplicaSet              deployment/relevance-scorer                     Scaled up replica set relevance-scorer-cd555d678 from 1 to 2
41m         Normal    Pulling                        pod/relevance-scorer-cd555d678-xgdtx            Pulling image "caffeinatedkong/relevance-scorer:latest"
41m         Normal    Created                        pod/relevance-scorer-cd555d678-xgdtx            Created container: relevance-scorer
41m         Normal    Started                        pod/relevance-scorer-cd555d678-xgdtx            Started container relevance-scorer
41m         Normal    Pulled                         pod/relevance-scorer-cd555d678-xgdtx            Successfully pulled image "caffeinatedkong/relevance-scorer:latest" in 3.49s (3.49s including waiting). Image size: 898174856 bytes.
41m         Warning   Unhealthy                      pod/relevance-scorer-cd555d678-xgdtx            Readiness probe failed: dial tcp 10.244.0.166:50052: connect: connection refused
40m         Normal    SuccessfulRescale              horizontalpodautoscaler/relevance-scorer-hpa    New size: 3; reason: cpu resource utilization (percentage of request) above target
40m         Normal    ScalingReplicaSet              deployment/relevance-scorer                     Scaled up replica set relevance-scorer-cd555d678 from 2 to 3
40m         Normal    SuccessfulCreate               replicaset/relevance-scorer-cd555d678           Created pod: relevance-scorer-cd555d678-dntnc
39m         Normal    SuccessfulRescale              horizontalpodautoscaler/flask-app-hpa           New size: 2; reason: All metrics below target
39m         Normal    SuccessfulDelete               replicaset/flask-app-5886b89967                 Deleted pod: flask-app-5886b89967-7jzbh
39m         Normal    SuccessfulDelete               replicaset/flask-app-5886b89967                 Deleted pod: flask-app-5886b89967-h68v8
39m         Normal    ScalingReplicaSet              deployment/flask-app                            Scaled down replica set flask-app-5886b89967 from 4 to 2
35m         Normal    ScalingReplicaSet              deployment/review-classifier                    Scaled down replica set review-classifier-7cdcd474d8 from 2 to 1
35m         Normal    SuccessfulRescale              horizontalpodautoscaler/review-classifier-hpa   New size: 1; reason: All metrics below target
35m         Normal    SuccessfulDelete               replicaset/review-classifier-7cdcd474d8         Deleted pod: review-classifier-7cdcd474d8-746q5
34m         Normal    SuccessfulRescale              horizontalpodautoscaler/relevance-scorer-hpa    New size: 2; reason: All metrics below target
34m         Normal    ScalingReplicaSet              deployment/relevance-scorer                     Scaled down replica set relevance-scorer-cd555d678 from 3 to 2
34m         Normal    SuccessfulDelete               replicaset/relevance-scorer-cd555d678           Deleted pod: relevance-scorer-cd555d678-dntnc
33m         Normal    ScalingReplicaSet              deployment/relevance-scorer                     Scaled down replica set relevance-scorer-cd555d678 from 2 to 1
33m         Normal    SuccessfulDelete               replicaset/relevance-scorer-cd555d678           Deleted pod: relevance-scorer-cd555d678-xgdtx
33m         Normal    Killing                        pod/relevance-scorer-cd555d678-xgdtx            Stopping container relevance-scorer
33m         Normal    SuccessfulRescale              horizontalpodautoscaler/relevance-scorer-hpa    New size: 1; reason: All metrics below target
31m         Warning   Unhealthy                      pod/redis-6d9c5b88d4-zrwlg                      Liveness probe failed: command timed out: "redis-cli ping" timed out after 5s
31m         Warning   Unhealthy                      pod/redis-6d9c5b88d4-zrwlg                      Readiness probe failed: command timed out: "redis-cli ping" timed out after 3s
31m         Warning   Unhealthy                      pod/scheduler-6bbf94dcc-8hz2w                   Readiness probe failed: command timed out: "python -c import sys; sys.exit(0)" timed out after 3s
31m         Warning   Unhealthy                      pod/redis-6d9c5b88d4-zrwlg                      Liveness probe errored and resulted in unknown state: rpc error: code = Unknown desc = Cannot connect to the Docker daemon at unix:///var/run/docker.sock. Is the docker daemon running?
31m         Warning   Unhealthy                      pod/scheduler-6bbf94dcc-8hz2w                   Readiness probe errored and resulted in unknown state: rpc error: code = Unknown desc = Cannot connect to the Docker daemon at unix:///var/run/docker.sock. Is the docker daemon running?
31m         Warning   Unhealthy                      pod/redis-6d9c5b88d4-zrwlg                      Readiness probe errored and resulted in unknown state: rpc error: code = Unknown desc = Cannot connect to the Docker daemon at unix:///var/run/docker.sock. Is the docker daemon running?
31m         Warning   Unhealthy                      pod/flask-app-5886b89967-s5sgc                  Liveness probe failed: Get "http://10.244.0.154:5000/health": dial tcp 10.244.0.154:5000: connect: connection refused
30m         Warning   Unhealthy                      pod/relevance-scorer-cd555d678-6tmdr            Readiness probe failed: dial tcp 10.244.0.157:50052: connect: connection refused
30m         Warning   Unhealthy                      pod/flask-app-5886b89967-4zgfn                  Readiness probe failed: Get "http://10.244.0.165:5000/health": dial tcp 10.244.0.165:5000: connect: connection refused
30m         Warning   Unhealthy                      pod/flask-app-5886b89967-s5sgc                  Readiness probe failed: Get "http://10.244.0.154:5000/health": dial tcp 10.244.0.154:5000: connect: connection refused
30m         Warning   Unhealthy                      pod/flask-app-5886b89967-4zgfn                  Liveness probe failed: Get "http://10.244.0.165:5000/health": dial tcp 10.244.0.165:5000: connect: connection refused
30m         Warning   Unhealthy                      pod/scraper-548b7ddb9f-jssgw                    Readiness probe failed: dial tcp 10.244.0.155:50053: connect: connection refused
30m         Warning   Unhealthy                      pod/redis-6d9c5b88d4-zrwlg                      Liveness probe errored and resulted in unknown state: rpc error: code = Unknown desc = container not running (1dd8f424cced258fc18d6d4b905b22e04a5457133e3db9535de3a50ca75c8cd6)
30m         Warning   Unhealthy                      pod/redis-6d9c5b88d4-zrwlg                      Readiness probe errored and resulted in unknown state: rpc error: code = Unknown desc = container not running (1dd8f424cced258fc18d6d4b905b22e04a5457133e3db9535de3a50ca75c8cd6)
30m         Warning   Unhealthy                      pod/scheduler-6bbf94dcc-8hz2w                   Readiness probe errored and resulted in unknown state: rpc error: code = Unknown desc = container not running (aaa848dcb5993b07b0f9a3b0fe605150680e94e4818c285cd2a070a696aadbba)
30m         Warning   Unhealthy                      pod/scheduler-6bbf94dcc-8hz2w                   Liveness probe errored and resulted in unknown state: rpc error: code = Unknown desc = container not running (aaa848dcb5993b07b0f9a3b0fe605150680e94e4818c285cd2a070a696aadbba)
30m         Warning   FailedSync                     pod/relevance-scorer-cd555d678-6tmdr            error determining status: rpc error: code = Unavailable desc = connection error: desc = "transport: Error while dialing: dial unix /var/run/cri-dockerd.sock: connect: connection refused"
30m         Normal    SandboxChanged                 pod/mongo-store-7fb479c547-z4bjn                Pod sandbox changed, it will be killed and re-created.
30m         Normal    SandboxChanged                 pod/flask-app-5886b89967-4zgfn                  Pod sandbox changed, it will be killed and re-created.
30m         Normal    SandboxChanged                 pod/relevance-scorer-cd555d678-6tmdr            Pod sandbox changed, it will be killed and re-created.
30m         Warning   Unhealthy                      pod/flask-app-5886b89967-4zgfn                  Readiness probe failed: Get "http://10.244.0.165:5000/health": context deadline exceeded (Client.Timeout exceeded while awaiting headers)
30m         Normal    SandboxChanged                 pod/mongo-5cddd86795-v4s6n                      Pod sandbox changed, it will be killed and re-created.
30m         Normal    SandboxChanged                 pod/review-classifier-85c4497458-ljdxf          Pod sandbox changed, it will be killed and re-created.
30m         Warning   Unhealthy                      pod/relevance-scorer-cd555d678-6tmdr            Liveness probe failed: dial tcp 10.244.0.157:50052: connect: no route to host
30m         Warning   Unhealthy                      pod/scraper-548b7ddb9f-jssgw                    Readiness probe failed: dial tcp 10.244.0.155:50053: connect: no route to host
30m         Normal    SandboxChanged                 pod/flask-app-5886b89967-s5sgc                  Pod sandbox changed, it will be killed and re-created.
30m         Warning   Unhealthy                      pod/scraper-548b7ddb9f-jssgw                    Liveness probe failed: dial tcp 10.244.0.155:50053: connect: no route to host
30m         Normal    SandboxChanged                 pod/scheduler-6bbf94dcc-8hz2w                   Pod sandbox changed, it will be killed and re-created.
30m         Warning   Unhealthy                      pod/relevance-scorer-cd555d678-6tmdr            Readiness probe failed: dial tcp 10.244.0.157:50052: connect: no route to host
30m         Warning   Unhealthy                      pod/flask-app-5886b89967-s5sgc                  Readiness probe failed: Get "http://10.244.0.154:5000/health": context deadline exceeded (Client.Timeout exceeded while awaiting headers)
30m         Normal    SandboxChanged                 pod/scraper-548b7ddb9f-jssgw                    Pod sandbox changed, it will be killed and re-created.
30m         Warning   Unhealthy                      pod/mongo-store-7fb479c547-z4bjn                Readiness probe failed: dial tcp 10.244.0.163:50054: i/o timeout
30m         Normal    SandboxChanged                 pod/redis-6d9c5b88d4-zrwlg                      Pod sandbox changed, it will be killed and re-created.
30m         Warning   Unhealthy                      pod/flask-app-5886b89967-s5sgc                  Liveness probe failed: Get "http://10.244.0.154:5000/health": dial tcp 10.244.0.154:5000: connect: no route to host
30m         Normal    Pulling                        pod/flask-app-5886b89967-s5sgc                  Pulling image "caffeinatedkong/flask-app:latest"
30m         Normal    Pulled                         pod/mongo-5cddd86795-v4s6n                      Container image "mongo:7" already present on machine
30m         Normal    Pulling                        pod/scheduler-6bbf94dcc-8hz2w                   Pulling image "caffeinatedkong/scheduler:latest"
30m         Normal    Created                        pod/mongo-5cddd86795-v4s6n                      Created container: mongo
30m         Normal    Pulling                        pod/scraper-548b7ddb9f-jssgw                    Pulling image "caffeinatedkong/scraper:latest"
30m         Normal    Started                        pod/mongo-5cddd86795-v4s6n                      Started container mongo
30m         Normal    Pulling                        pod/redis-6d9c5b88d4-zrwlg                      Pulling image "redis:latest"
30m         Normal    Pulled                         pod/relevance-scorer-cd555d678-6tmdr            Successfully pulled image "caffeinatedkong/relevance-scorer:latest" in 4.661s (4.662s including waiting). Image size: 898174856 bytes.
30m         Warning   Failed                         pod/relevance-scorer-cd555d678-6tmdr            Error: failed to sync configmap cache: timed out waiting for the condition
30m         Normal    Pulling                        pod/relevance-scorer-cd555d678-6tmdr            Pulling image "caffeinatedkong/relevance-scorer:latest"
30m         Normal    Pulled                         pod/flask-app-5886b89967-4zgfn                  Successfully pulled image "caffeinatedkong/flask-app:latest" in 2.833s (7.402s including waiting). Image size: 749810154 bytes.
30m         Warning   Failed                         pod/flask-app-5886b89967-4zgfn                  Error: failed to sync configmap cache: timed out waiting for the condition
30m         Normal    Pulling                        pod/flask-app-5886b89967-4zgfn                  Pulling image "caffeinatedkong/flask-app:latest"
30m         Normal    Pulled                         pod/mongo-store-7fb479c547-z4bjn                Successfully pulled image "caffeinatedkong/mongo-store:latest" in 2.748s (8.589s including waiting). Image size: 520025736 bytes.
30m         Normal    Pulling                        pod/mongo-store-7fb479c547-z4bjn                Pulling image "caffeinatedkong/mongo-store:latest"
30m         Warning   Failed                         pod/mongo-store-7fb479c547-z4bjn                Error: failed to sync configmap cache: timed out waiting for the condition
30m         Normal    Pulled                         pod/review-classifier-85c4497458-ljdxf          Successfully pulled image "caffeinatedkong/review-classifier:latest" in 2.828s (11.224s including waiting). Image size: 1872336796 bytes.
30m         Warning   Failed                         pod/review-classifier-85c4497458-ljdxf          Error: failed to sync configmap cache: timed out waiting for the condition
30m         Normal    Pulling                        pod/review-classifier-85c4497458-ljdxf          Pulling image "caffeinatedkong/review-classifier:latest"
30m         Normal    Started                        pod/scheduler-6bbf94dcc-8hz2w                   Started container scheduler
30m         Normal    Pulled                         pod/scheduler-6bbf94dcc-8hz2w                   Successfully pulled image "caffeinatedkong/scheduler:latest" in 2.724s (13.305s including waiting). Image size: 487939183 bytes.
30m         Normal    Created                        pod/scheduler-6bbf94dcc-8hz2w                   Created container: scheduler
30m         Normal    Created                        pod/flask-app-5886b89967-s5sgc                  Created container: flask-app
30m         Normal    Started                        pod/flask-app-5886b89967-s5sgc                  Started container flask-app
30m         Normal    Pulled                         pod/flask-app-5886b89967-s5sgc                  Successfully pulled image "caffeinatedkong/flask-app:latest" in 2.417s (15.656s including waiting). Image size: 749810154 bytes.
30m         Normal    Started                        pod/scraper-548b7ddb9f-jssgw                    Started container scraper
30m         Normal    Pulled                         pod/scraper-548b7ddb9f-jssgw                    Successfully pulled image "caffeinatedkong/scraper:latest" in 2.516s (17.859s including waiting). Image size: 523842750 bytes.
30m         Normal    Created                        pod/scraper-548b7ddb9f-jssgw                    Created container: scraper
30m         Normal    Created                        pod/redis-6d9c5b88d4-zrwlg                      Created container: redis
30m         Normal    Started                        pod/redis-6d9c5b88d4-zrwlg                      Started container redis
30m         Normal    Pulled                         pod/redis-6d9c5b88d4-zrwlg                      Successfully pulled image "redis:latest" in 2.506s (19.771s including waiting). Image size: 137229198 bytes.
30m         Normal    Created                        pod/relevance-scorer-cd555d678-6tmdr            Created container: relevance-scorer
30m         Normal    Started                        pod/relevance-scorer-cd555d678-6tmdr            Started container relevance-scorer
30m         Normal    Pulled                         pod/relevance-scorer-cd555d678-6tmdr            Successfully pulled image "caffeinatedkong/relevance-scorer:latest" in 2.457s (19.038s including waiting). Image size: 898174856 bytes.
30m         Normal    Created                        pod/flask-app-5886b89967-4zgfn                  Created container: flask-app
30m         Normal    Started                        pod/flask-app-5886b89967-4zgfn                  Started container flask-app
30m         Normal    Pulled                         pod/flask-app-5886b89967-4zgfn                  Successfully pulled image "caffeinatedkong/flask-app:latest" in 2.663s (19.615s including waiting). Image size: 749810154 bytes.
30m         Normal    Created                        pod/mongo-store-7fb479c547-z4bjn                Created container: mongo-store
30m         Normal    Pulled                         pod/mongo-store-7fb479c547-z4bjn                Successfully pulled image "caffeinatedkong/mongo-store:latest" in 2.347s (18.89s including waiting). Image size: 520025736 bytes.
30m         Normal    Started                        pod/mongo-store-7fb479c547-z4bjn                Started container mongo-store
30m         Normal    Pulled                         pod/review-classifier-85c4497458-ljdxf          Successfully pulled image "caffeinatedkong/review-classifier:latest" in 2.31s (18.749s including waiting). Image size: 1872336796 bytes.
30m         Normal    Started                        pod/review-classifier-85c4497458-ljdxf          Started container review-classifier
30m         Normal    Created                        pod/review-classifier-85c4497458-ljdxf          Created container: review-classifier
30m         Warning   Unhealthy                      pod/relevance-scorer-cd555d678-6tmdr            Readiness probe failed: dial tcp 10.244.0.168:50052: connect: connection refused
29m         Warning   FailedGetResourceMetric        horizontalpodautoscaler/review-classifier-hpa   failed to get cpu utilization: unable to get metrics for resource cpu: no metrics returned from resource metrics API
29m         Warning   FailedComputeMetricsReplicas   horizontalpodautoscaler/review-classifier-hpa   invalid metrics (1 invalid out of 1), first error is: failed to get cpu resource metric value: failed to get cpu utilization: unable to get metrics for resource cpu: no metrics returned from resource metrics API
29m         Warning   FailedComputeMetricsReplicas   horizontalpodautoscaler/relevance-scorer-hpa    invalid metrics (1 invalid out of 1), first error is: failed to get cpu resource metric value: failed to get cpu utilization: unable to get metrics for resource cpu: no metrics returned from resource metrics API
29m         Warning   FailedComputeMetricsReplicas   horizontalpodautoscaler/flask-app-hpa           invalid metrics (2 invalid out of 2), first error is: failed to get cpu resource metric value: failed to get cpu utilization: unable to get metrics for resource cpu: no metrics returned from resource metrics API
29m         Warning   FailedGetResourceMetric        horizontalpodautoscaler/flask-app-hpa           failed to get memory utilization: unable to get metrics for resource memory: no metrics returned from resource metrics API
29m         Warning   FailedGetResourceMetric        horizontalpodautoscaler/flask-app-hpa           failed to get cpu utilization: unable to get metrics for resource cpu: no metrics returned from resource metrics API
29m         Warning   FailedGetResourceMetric        horizontalpodautoscaler/relevance-scorer-hpa    failed to get cpu utilization: unable to get metrics for resource cpu: no metrics returned from resource metrics API
29m         Warning   FailedGetResourceMetric        horizontalpodautoscaler/mongo-store-hpa         failed to get cpu utilization: unable to get metrics for resource cpu: no metrics returned from resource metrics API
29m         Warning   FailedGetResourceMetric        horizontalpodautoscaler/scraper-hpa             failed to get cpu utilization: unable to get metrics for resource cpu: no metrics returned from resource metrics API
29m         Warning   FailedComputeMetricsReplicas   horizontalpodautoscaler/scraper-hpa             invalid metrics (1 invalid out of 1), first error is: failed to get cpu resource metric value: failed to get cpu utilization: unable to get metrics for resource cpu: no metrics returned from resource metrics API
29m         Warning   FailedComputeMetricsReplicas   horizontalpodautoscaler/mongo-store-hpa         invalid metrics (1 invalid out of 1), first error is: failed to get cpu resource metric value: failed to get cpu utilization: unable to get metrics for resource cpu: no metrics returned from resource metrics API
29m         Normal    Sync                           ingress/fraud-buster-ingress                    Scheduled for sync
29m         Normal    SuccessfulRescale              horizontalpodautoscaler/review-classifier-hpa   New size: 2; reason: cpu resource utilization (percentage of request) above target
29m         Normal    ScalingReplicaSet              deployment/review-classifier                    Scaled up replica set review-classifier-7cdcd474d8 from 1 to 2
29m         Normal    SuccessfulRescale              horizontalpodautoscaler/relevance-scorer-hpa    New size: 2; reason: cpu resource utilization (percentage of request) above target
29m         Normal    ScalingReplicaSet              deployment/relevance-scorer                     Scaled up replica set relevance-scorer-cd555d678 from 1 to 2
29m         Normal    SuccessfulCreate               replicaset/relevance-scorer-cd555d678           Created pod: relevance-scorer-cd555d678-77xm6
29m         Normal    SuccessfulCreate               replicaset/review-classifier-7cdcd474d8         Created pod: review-classifier-7cdcd474d8-pfk4f
29m         Normal    Pulling                        pod/relevance-scorer-cd555d678-77xm6            Pulling image "caffeinatedkong/relevance-scorer:latest"
29m         Normal    Pulled                         pod/relevance-scorer-cd555d678-77xm6            Successfully pulled image "caffeinatedkong/relevance-scorer:latest" in 2.612s (2.612s including waiting). Image size: 898174856 bytes.
29m         Normal    Created                        pod/relevance-scorer-cd555d678-77xm6            Created container: relevance-scorer
29m         Normal    Started                        pod/relevance-scorer-cd555d678-77xm6            Started container relevance-scorer
29m         Warning   Unhealthy                      pod/relevance-scorer-cd555d678-77xm6            Readiness probe failed: dial tcp 10.244.0.179:50052: connect: connection refused
28m         Normal    SuccessfulCreate               replicaset/relevance-scorer-cd555d678           Created pod: relevance-scorer-cd555d678-lp5wf
28m         Normal    SuccessfulRescale              horizontalpodautoscaler/relevance-scorer-hpa    New size: 3; reason: cpu resource utilization (percentage of request) above target
28m         Normal    ScalingReplicaSet              deployment/relevance-scorer                     Scaled up replica set relevance-scorer-cd555d678 from 2 to 3
23m         Normal    SuccessfulRescale              horizontalpodautoscaler/review-classifier-hpa   New size: 1; reason: All metrics below target
23m         Normal    ScalingReplicaSet              deployment/review-classifier                    Scaled down replica set review-classifier-7cdcd474d8 from 2 to 1
23m         Normal    SuccessfulDelete               replicaset/review-classifier-7cdcd474d8         Deleted pod: review-classifier-7cdcd474d8-pfk4f
22m         Normal    ScalingReplicaSet              deployment/relevance-scorer                     Scaled down replica set relevance-scorer-cd555d678 from 3 to 1
22m         Normal    Killing                        pod/relevance-scorer-cd555d678-77xm6            Stopping container relevance-scorer
22m         Normal    SuccessfulRescale              horizontalpodautoscaler/relevance-scorer-hpa    New size: 1; reason: All metrics below target
22m         Normal    SuccessfulDelete               replicaset/relevance-scorer-cd555d678           Deleted pod: relevance-scorer-cd555d678-lp5wf
22m         Normal    SuccessfulDelete               replicaset/relevance-scorer-cd555d678           Deleted pod: relevance-scorer-cd555d678-77xm6
9m26s       Normal    SuccessfulCreate               replicaset/flask-app-5886b89967                 Created pod: flask-app-5886b89967-c5z86
9m26s       Normal    ScalingReplicaSet              deployment/flask-app                            Scaled up replica set flask-app-5886b89967 from 2 to 4
9m26s       Normal    SuccessfulRescale              horizontalpodautoscaler/flask-app-hpa           New size: 4; reason: cpu resource utilization (percentage of request) above target
9m26s       Normal    SuccessfulCreate               replicaset/flask-app-5886b89967                 Created pod: flask-app-5886b89967-sd6nr
9m22s       Normal    Pulling                        pod/flask-app-5886b89967-sd6nr                  Pulling image "caffeinatedkong/flask-app:latest"
9m19s       Normal    Pulled                         pod/flask-app-5886b89967-sd6nr                  Successfully pulled image "caffeinatedkong/flask-app:latest" in 2.908s (2.908s including waiting). Image size: 749810154 bytes.
9m18s       Normal    Created                        pod/flask-app-5886b89967-sd6nr                  Created container: flask-app
9m18s       Normal    Started                        pod/flask-app-5886b89967-sd6nr                  Started container flask-app
8m56s       Normal    SuccessfulRescale              horizontalpodautoscaler/flask-app-hpa           New size: 5; reason: cpu resource utilization (percentage of request) above target
8m56s       Normal    ScalingReplicaSet              deployment/flask-app                            Scaled up replica set flask-app-5886b89967 from 4 to 5
8m56s       Normal    SuccessfulCreate               replicaset/flask-app-5886b89967                 Created pod: flask-app-5886b89967-kttqg
8m26s       Normal    ScalingReplicaSet              deployment/flask-app                            Scaled up replica set flask-app-5886b89967 from 5 to 8
8m26s       Normal    SuccessfulCreate               replicaset/flask-app-5886b89967                 Created pod: flask-app-5886b89967-jclvb
8m26s       Normal    SuccessfulCreate               replicaset/flask-app-5886b89967                 Created pod: flask-app-5886b89967-994qg
8m26s       Normal    SuccessfulCreate               replicaset/flask-app-5886b89967                 Created pod: flask-app-5886b89967-mth6m
8m26s       Normal    SuccessfulRescale              horizontalpodautoscaler/flask-app-hpa           New size: 8; reason: cpu resource utilization (percentage of request) above target
115s        Normal    SuccessfulDelete               replicaset/flask-app-5886b89967                 Deleted pod: flask-app-5886b89967-mth6m
115s        Normal    SuccessfulDelete               replicaset/flask-app-5886b89967                 Deleted pod: flask-app-5886b89967-kttqg
115s        Normal    SuccessfulDelete               replicaset/flask-app-5886b89967                 Deleted pod: flask-app-5886b89967-994qg
115s        Normal    SuccessfulDelete               replicaset/flask-app-5886b89967                 Deleted pod: flask-app-5886b89967-c5z86
115s        Normal    SuccessfulRescale              horizontalpodautoscaler/flask-app-hpa           New size: 4; reason: All metrics below target
115s        Normal    ScalingReplicaSet              deployment/flask-app                            Scaled down replica set flask-app-5886b89967 from 8 to 4
55s         Normal    Killing                        pod/flask-app-5886b89967-sd6nr                  Stopping container flask-app
55s         Normal    SuccessfulDelete               replicaset/flask-app-5886b89967                 Deleted pod: flask-app-5886b89967-sd6nr
55s         Normal    SuccessfulDelete               replicaset/flask-app-5886b89967                 Deleted pod: flask-app-5886b89967-jclvb
55s         Normal    SuccessfulRescale              horizontalpodautoscaler/flask-app-hpa           New size: 2; reason: All metrics below target
55s         Normal    ScalingReplicaSet              deployment/flask-app                            Scaled down replica set flask-app-5886b89967 from 4 to 2
