LAST SEEN   TYPE      REASON              OBJECT                                   MESSAGE
54m         Warning   FailedScheduling    pod/flask-app-5886b89967-mth6m           0/1 nodes are available: 1 Insufficient memory. no new claims to deallocate, preemption: 0/1 nodes are available: 1 No preemption victims found for incoming pod.
60m         Warning   FailedScheduling    pod/flask-app-5886b89967-994qg           0/1 nodes are available: 1 Insufficient memory. no new claims to deallocate, preemption: 0/1 nodes are available: 1 No preemption victims found for incoming pod.
55m         Warning   FailedScheduling    pod/flask-app-5886b89967-c5z86           0/1 nodes are available: 1 Insufficient memory. no new claims to deallocate, preemption: 0/1 nodes are available: 1 No preemption victims found for incoming pod.
60m         Warning   FailedScheduling    pod/flask-app-5886b89967-jclvb           0/1 nodes are available: 1 Insufficient memory. no new claims to deallocate, preemption: 0/1 nodes are available: 1 No preemption victims found for incoming pod.
54m         Warning   FailedScheduling    pod/flask-app-5886b89967-jclvb           0/1 nodes are available: 1 Insufficient memory. no new claims to deallocate, preemption: 0/1 nodes are available: 1 No preemption victims found for incoming pod.
55m         Warning   FailedScheduling    pod/flask-app-5886b89967-kttqg           0/1 nodes are available: 1 Insufficient memory. no new claims to deallocate, preemption: 0/1 nodes are available: 1 No preemption victims found for incoming pod.
27m         Warning   FailedScheduling    pod/review-classifier-7cdcd474d8-7rzwp   0/1 nodes are available: 1 Insufficient memory. no new claims to deallocate, preemption: 0/1 nodes are available: 1 No preemption victims found for incoming pod.
27m         Warning   FailedScheduling    pod/mongo-5dfcf95c47-mmwwg               0/1 nodes are available: 1 Insufficient memory. no new claims to deallocate, preemption: 0/1 nodes are available: 1 No preemption victims found for incoming pod.
54m         Warning   FailedScheduling    pod/flask-app-5886b89967-994qg           0/1 nodes are available: 1 Insufficient memory. no new claims to deallocate, preemption: 0/1 nodes are available: 1 No preemption victims found for incoming pod.
60m         Normal    SuccessfulCreate    replicaset/flask-app-5886b89967          Created pod: flask-app-5886b89967-994qg
60m         Normal    SuccessfulCreate    replicaset/flask-app-5886b89967          Created pod: flask-app-5886b89967-jclvb
60m         Normal    SuccessfulRescale   horizontalpodautoscaler/flask-app-hpa    New size: 8; reason: cpu resource utilization (percentage of request) above target
60m         Normal    SuccessfulCreate    replicaset/flask-app-5886b89967          Created pod: flask-app-5886b89967-mth6m
60m         Normal    ScalingReplicaSet   deployment/flask-app                     Scaled up replica set flask-app-5886b89967 from 5 to 8
53m         Normal    SuccessfulDelete    replicaset/flask-app-5886b89967          Deleted pod: flask-app-5886b89967-mth6m
53m         Normal    SuccessfulDelete    replicaset/flask-app-5886b89967          Deleted pod: flask-app-5886b89967-c5z86
53m         Normal    SuccessfulRescale   horizontalpodautoscaler/flask-app-hpa    New size: 4; reason: All metrics below target
53m         Normal    SuccessfulDelete    replicaset/flask-app-5886b89967          Deleted pod: flask-app-5886b89967-994qg
53m         Normal    ScalingReplicaSet   deployment/flask-app                     Scaled down replica set flask-app-5886b89967 from 8 to 4
53m         Normal    SuccessfulDelete    replicaset/flask-app-5886b89967          Deleted pod: flask-app-5886b89967-kttqg
52m         Normal    SuccessfulDelete    replicaset/flask-app-5886b89967          Deleted pod: flask-app-5886b89967-sd6nr
52m         Normal    SuccessfulDelete    replicaset/flask-app-5886b89967          Deleted pod: flask-app-5886b89967-jclvb
52m         Normal    SuccessfulRescale   horizontalpodautoscaler/flask-app-hpa    New size: 2; reason: All metrics below target
52m         Normal    ScalingReplicaSet   deployment/flask-app                     Scaled down replica set flask-app-5886b89967 from 4 to 2
52m         Normal    Killing             pod/flask-app-5886b89967-sd6nr           Stopping container flask-app
