LAST SEEN   TYPE      REASON              OBJECT                                          MESSAGE
6m38s       Warning   FailedScheduling    pod/relevance-scorer-cd555d678-zt7qd            0/1 nodes are available: 1 Insufficient memory. no new claims to deallocate, preemption: 0/1 nodes are available: 1 No preemption victims found for incoming pod.
13m         Normal    Scheduled           pod/relevance-scorer-cd555d678-6z2dc            Successfully assigned fraud-buster/relevance-scorer-cd555d678-6z2dc to minikube
16m         Warning   FailedScheduling    pod/mongo-5dfcf95c47-mmwwg                      0/1 nodes are available: 1 Insufficient memory. no new claims to deallocate, preemption: 0/1 nodes are available: 1 No preemption victims found for incoming pod.
7m38s       Warning   FailedScheduling    pod/review-classifier-7cdcd474d8-dtr65          0/1 nodes are available: 1 Insufficient memory. no new claims to deallocate, preemption: 0/1 nodes are available: 1 No preemption victims found for incoming pod.
13m         Warning   FailedScheduling    pod/review-classifier-7cdcd474d8-dtr65          0/1 nodes are available: 1 Insufficient memory. no new claims to deallocate, preemption: 0/1 nodes are available: 1 No preemption victims found for incoming pod.
15m         Warning   FailedScheduling    pod/review-classifier-7cdcd474d8-7rzwp          0/1 nodes are available: 1 Insufficient memory. no new claims to deallocate, preemption: 0/1 nodes are available: 1 No preemption victims found for incoming pod.
12m         Warning   FailedScheduling    pod/relevance-scorer-cd555d678-zt7qd            0/1 nodes are available: 1 Insufficient memory. no new claims to deallocate, preemption: 0/1 nodes are available: 1 No preemption victims found for incoming pod.
13m         Normal    ScalingReplicaSet   deployment/review-classifier                    Scaled up replica set review-classifier-7cdcd474d8 from 1 to 2
13m         Normal    ScalingReplicaSet   deployment/relevance-scorer                     Scaled up replica set relevance-scorer-cd555d678 from 1 to 2
13m         Normal    SuccessfulRescale   horizontalpodautoscaler/relevance-scorer-hpa    New size: 2; reason: cpu resource utilization (percentage of request) above target
13m         Normal    SuccessfulRescale   horizontalpodautoscaler/review-classifier-hpa   New size: 2; reason: cpu resource utilization (percentage of request) above target
13m         Normal    SuccessfulCreate    replicaset/relevance-scorer-cd555d678           Created pod: relevance-scorer-cd555d678-6z2dc
13m         Normal    SuccessfulCreate    replicaset/review-classifier-7cdcd474d8         Created pod: review-classifier-7cdcd474d8-dtr65
13m         Normal    Pulling             pod/relevance-scorer-cd555d678-6z2dc            Pulling image "caffeinatedkong/relevance-scorer:latest"
12m         Normal    Created             pod/relevance-scorer-cd555d678-6z2dc            Created container: relevance-scorer
12m         Normal    Pulled              pod/relevance-scorer-cd555d678-6z2dc            Successfully pulled image "caffeinatedkong/relevance-scorer:latest" in 2.745s (2.746s including waiting). Image size: 898174856 bytes.
12m         Normal    Started             pod/relevance-scorer-cd555d678-6z2dc            Started container relevance-scorer
12m         Warning   Unhealthy           pod/redis-6d9c5b88d4-zrwlg                      Readiness probe failed: command timed out: "redis-cli ping" timed out after 3s
12m         Warning   Unhealthy           pod/relevance-scorer-cd555d678-6z2dc            Liveness probe failed: dial tcp 10.244.0.181:50052: connect: connection refused
12m         Warning   Unhealthy           pod/relevance-scorer-cd555d678-6z2dc            Readiness probe failed: dial tcp 10.244.0.181:50052: connect: connection refused
12m         Normal    SuccessfulRescale   horizontalpodautoscaler/relevance-scorer-hpa    New size: 3; reason: cpu resource utilization (percentage of request) above target
12m         Normal    SuccessfulCreate    replicaset/relevance-scorer-cd555d678           Created pod: relevance-scorer-cd555d678-zt7qd
12m         Normal    ScalingReplicaSet   deployment/relevance-scorer                     Scaled up replica set relevance-scorer-cd555d678 from 2 to 3
6m18s       Normal    SuccessfulRescale   horizontalpodautoscaler/review-classifier-hpa   New size: 1; reason: All metrics below target
6m18s       Normal    ScalingReplicaSet   deployment/review-classifier                    Scaled down replica set review-classifier-7cdcd474d8 from 2 to 1
6m18s       Normal    SuccessfulDelete    replicaset/review-classifier-7cdcd474d8         Deleted pod: review-classifier-7cdcd474d8-dtr65
5m18s       Normal    SuccessfulDelete    replicaset/relevance-scorer-cd555d678           Deleted pod: relevance-scorer-cd555d678-6z2dc
5m18s       Normal    ScalingReplicaSet   deployment/relevance-scorer                     Scaled down replica set relevance-scorer-cd555d678 from 3 to 1
5m18s       Normal    SuccessfulRescale   horizontalpodautoscaler/relevance-scorer-hpa    New size: 1; reason: All metrics below target
5m18s       Normal    SuccessfulDelete    replicaset/relevance-scorer-cd555d678           Deleted pod: relevance-scorer-cd555d678-zt7qd
5m18s       Normal    Killing             pod/relevance-scorer-cd555d678-6z2dc            Stopping container relevance-scorer
