LAST SEEN   TYPE      REASON                         OBJECT                                          MESSAGE
34m         Warning   FailedScheduling               pod/flask-app-5886b89967-g67j6                  0/1 nodes are available: 1 Insufficient memory. no new claims to deallocate, preemption: 0/1 nodes are available: 1 No preemption victims found for incoming pod.
4m24s       Warning   FailedScheduling               pod/flask-app-5886b89967-zz5lt                  0/1 nodes are available: 1 Insufficient memory. no new claims to deallocate, preemption: 0/1 nodes are available: 1 No preemption victims found for incoming pod.
4m54s       Warning   FailedScheduling               pod/flask-app-5886b89967-m48x2                  0/1 nodes are available: 1 Insufficient memory. no new claims to deallocate, preemption: 0/1 nodes are available: 1 No preemption victims found for incoming pod.
4m24s       Warning   FailedScheduling               pod/flask-app-5886b89967-kc2nn                  0/1 nodes are available: 1 Insufficient memory. no new claims to deallocate, preemption: 0/1 nodes are available: 1 No preemption victims found for incoming pod.
4m24s       Warning   FailedScheduling               pod/flask-app-5886b89967-vsfhc                  0/1 nodes are available: 1 Insufficient memory. no new claims to deallocate, preemption: 0/1 nodes are available: 1 No preemption victims found for incoming pod.
5m36s       Warning   FailedScheduling               pod/review-classifier-7cdcd474d8-7rzwp          0/1 nodes are available: 1 Insufficient memory. no new claims to deallocate, preemption: 0/1 nodes are available: 1 No preemption victims found for incoming pod.
34m         Warning   FailedScheduling               pod/review-classifier-7cdcd474d8-7rzwp          0/1 nodes are available: 1 node(s) had untolerated taint {node.kubernetes.io/not-ready: }. no new claims to deallocate, preemption: 0/1 nodes are available: 1 Preemption is not helpful for scheduling.
34m         Warning   FailedScheduling               pod/relevance-scorer-cd555d678-cbbgx            0/1 nodes are available: 1 Insufficient memory. no new claims to deallocate, preemption: 0/1 nodes are available: 1 No preemption victims found for incoming pod.
33m         Normal    Scheduled                      pod/flask-app-5886b89967-g67j6                  Successfully assigned fraud-buster/flask-app-5886b89967-g67j6 to minikube
4m54s       Normal    Scheduled                      pod/flask-app-5886b89967-gs9rc                  Successfully assigned fraud-buster/flask-app-5886b89967-gs9rc to minikube
5m36s       Warning   FailedScheduling               pod/mongo-5dfcf95c47-mmwwg                      0/1 nodes are available: 1 Insufficient memory. no new claims to deallocate, preemption: 0/1 nodes are available: 1 No preemption victims found for incoming pod.
34m         Warning   FailedScheduling               pod/flask-app-5886b89967-9qtnw                  0/1 nodes are available: 1 Insufficient memory. no new claims to deallocate, preemption: 0/1 nodes are available: 1 No preemption victims found for incoming pod.
34m         Warning   FailedScheduling               pod/scraper-548b7ddb9f-4j7v6                    0/1 nodes are available: 1 Insufficient memory. no new claims to deallocate, preemption: 0/1 nodes are available: 1 No preemption victims found for incoming pod.
4m24s       Warning   FailedScheduling               pod/flask-app-5886b89967-vdv68                  0/1 nodes are available: 1 Insufficient memory. no new claims to deallocate, preemption: 0/1 nodes are available: 1 No preemption victims found for incoming pod.
34m         Warning   FailedScheduling               pod/mongo-5dfcf95c47-mmwwg                      0/1 nodes are available: 1 node(s) had untolerated taint {node.kubernetes.io/not-ready: }. no new claims to deallocate, preemption: 0/1 nodes are available: 1 Preemption is not helpful for scheduling.
2m54s       Warning   FailedScheduling               pod/mongo-store-7fb479c547-gtm82                0/1 nodes are available: 1 Insufficient memory. no new claims to deallocate, preemption: 0/1 nodes are available: 1 No preemption victims found for incoming pod.
4m54s       Warning   FailedScheduling               pod/mongo-store-7fb479c547-4t94z                0/1 nodes are available: 1 Insufficient memory. no new claims to deallocate, preemption: 0/1 nodes are available: 1 No preemption victims found for incoming pod.
61m         Warning   Failed                         pod/redis-6d9c5b88d4-zrwlg                      Error: context deadline exceeded
61m         Warning   Unhealthy                      pod/redis-6d9c5b88d4-zrwlg                      Readiness probe errored and resulted in unknown state: rpc error: code = Unknown desc = container not running (3abae06ada829d6e1f81ddd101001ebeb8fb7fb54cd99e2ac62fc76cc2033f65)
61m         Warning   Unhealthy                      pod/scheduler-6bbf94dcc-8hz2w                   Readiness probe failed: FailedPrecondition: container c1b92d3b812a4d43a7ceb2b5053368de2244da2b94d051b4a0e01f8f50882dbb init process is not running: failed precondition
61m         Warning   Unhealthy                      pod/scheduler-6bbf94dcc-8hz2w                   Readiness probe errored and resulted in unknown state: rpc error: code = Unknown desc = container not running (c1b92d3b812a4d43a7ceb2b5053368de2244da2b94d051b4a0e01f8f50882dbb)
61m         Warning   Unhealthy                      pod/redis-6d9c5b88d4-zrwlg                      Readiness probe failed: Could not connect to Redis at 127.0.0.1:6379: Connection refused
61m         Normal    Pulled                         pod/scheduler-6bbf94dcc-8hz2w                   Successfully pulled image "caffeinatedkong/scheduler:latest" in 3.078s (3.078s including waiting). Image size: 487939183 bytes.
44m         Warning   NodeNotReady                   pod/redis-6d9c5b88d4-zrwlg                      Node is not ready
44m         Warning   FailedComputeMetricsReplicas   horizontalpodautoscaler/flask-app-hpa           invalid metrics (2 invalid out of 2), first error is: failed to get cpu resource metric value: failed to get cpu utilization: unable to get metrics for resource cpu: unable to fetch metrics from resource metrics API: the server is currently unable to handle the request (get pods.metrics.k8s.io)
44m         Warning   FailedGetResourceMetric        horizontalpodautoscaler/flask-app-hpa           failed to get memory utilization: unable to get metrics for resource memory: unable to fetch metrics from resource metrics API: the server is currently unable to handle the request (get pods.metrics.k8s.io)
44m         Warning   Unhealthy                      pod/redis-6d9c5b88d4-zrwlg                      Liveness probe failed: command timed out: "redis-cli ping" timed out after 5s
43m         Warning   Unhealthy                      pod/redis-6d9c5b88d4-zrwlg                      Readiness probe failed: command timed out: "redis-cli ping" timed out after 3s
43m         Normal    Killing                        pod/redis-6d9c5b88d4-zrwlg                      Container redis failed liveness probe, will be restarted
43m         Warning   Unhealthy                      pod/redis-6d9c5b88d4-zrwlg                      Readiness probe failed:
43m         Normal    Pulled                         pod/redis-6d9c5b88d4-zrwlg                      Successfully pulled image "redis:latest" in 3.281s (3.281s including waiting). Image size: 137229198 bytes.
37m         Warning   Unhealthy                      pod/scheduler-6bbf94dcc-8hz2w                   Liveness probe failed: command timed out: "python -c import sys; sys.exit(0)" timed out after 5s
37m         Warning   Unhealthy                      pod/redis-6d9c5b88d4-zrwlg                      Readiness probe errored and resulted in unknown state: rpc error: code = Unknown desc = container not running (92f00eb4cbfa57e7c2ca2fb94789305fde863ac6394f22478942640a52c398d0)
37m         Warning   FailedMount                    pod/review-classifier-85c4497458-ljdxf          MountVolume.SetUp failed for volume "kube-api-access-s7vj9" : failed to sync configmap cache: timed out waiting for the condition
37m         Warning   FailedMount                    pod/scraper-548b7ddb9f-jssgw                    MountVolume.SetUp failed for volume "kube-api-access-w2c9d" : failed to sync configmap cache: timed out waiting for the condition
37m         Warning   FailedMount                    pod/flask-app-5886b89967-s5sgc                  MountVolume.SetUp failed for volume "kube-api-access-pxlf8" : failed to sync configmap cache: timed out waiting for the condition
37m         Warning   FailedMount                    pod/mongo-store-7fb479c547-z4bjn                MountVolume.SetUp failed for volume "kube-api-access-m7bbd" : failed to sync configmap cache: timed out waiting for the condition
37m         Warning   FailedMount                    pod/relevance-scorer-cd555d678-gww9t            MountVolume.SetUp failed for volume "kube-api-access-vdgbf" : failed to sync configmap cache: timed out waiting for the condition
37m         Warning   FailedMount                    pod/scheduler-6bbf94dcc-8hz2w                   MountVolume.SetUp failed for volume "kube-api-access-6jg55" : failed to sync configmap cache: timed out waiting for the condition
37m         Warning   FailedMount                    pod/flask-app-5886b89967-4zgfn                  MountVolume.SetUp failed for volume "kube-api-access-t77f5" : failed to sync configmap cache: timed out waiting for the condition
37m         Normal    Sync                           ingress/fraud-buster-ingress                    Scheduled for sync
37m         Warning   FailedGetResourceMetric        horizontalpodautoscaler/flask-app-hpa           failed to get cpu utilization: unable to get metrics for resource cpu: unable to fetch metrics from resource metrics API: the server is currently unable to handle the request (get pods.metrics.k8s.io)
37m         Warning   NodeNotReady                   pod/mongo-5cddd86795-v4s6n                      Node is not ready
37m         Warning   Unhealthy                      pod/scheduler-6bbf94dcc-8hz2w                   Readiness probe failed: command timed out: "python -c import sys; sys.exit(0)" timed out after 3s
37m         Warning   NodeNotReady                   pod/flask-app-5886b89967-s5sgc                  Node is not ready
37m         Warning   NodeNotReady                   pod/scraper-548b7ddb9f-jssgw                    Node is not ready
37m         Warning   FailedScheduling               pod/mongo-5dfcf95c47-mmwwg                      0/1 nodes are available: 1 node(s) had untolerated taint {node.kubernetes.io/unreachable: }. no new claims to deallocate, preemption: 0/1 nodes are available: 1 Preemption is not helpful for scheduling.
37m         Warning   NodeNotReady                   pod/mongo-store-7fb479c547-z4bjn                Node is not ready
37m         Warning   NodeNotReady                   pod/relevance-scorer-cd555d678-gww9t            Node is not ready
37m         Warning   FailedScheduling               pod/review-classifier-7cdcd474d8-7rzwp          0/1 nodes are available: 1 node(s) had untolerated taint {node.kubernetes.io/unreachable: }. no new claims to deallocate, preemption: 0/1 nodes are available: 1 Preemption is not helpful for scheduling.
37m         Warning   NodeNotReady                   pod/flask-app-5886b89967-4zgfn                  Node is not ready
37m         Warning   NodeNotReady                   pod/scheduler-6bbf94dcc-8hz2w                   Node is not ready
37m         Warning   NodeNotReady                   pod/review-classifier-85c4497458-ljdxf          Node is not ready
37m         Normal    Killing                        pod/scheduler-6bbf94dcc-8hz2w                   Container scheduler failed liveness probe, will be restarted
37m         Normal    TaintManagerEviction           pod/flask-app-5886b89967-4zgfn                  Cancelling deletion of Pod fraud-buster/flask-app-5886b89967-4zgfn
37m         Normal    TaintManagerEviction           pod/mongo-store-7fb479c547-z4bjn                Cancelling deletion of Pod fraud-buster/mongo-store-7fb479c547-z4bjn
37m         Normal    TaintManagerEviction           pod/review-classifier-85c4497458-ljdxf          Cancelling deletion of Pod fraud-buster/review-classifier-85c4497458-ljdxf
37m         Normal    TaintManagerEviction           pod/flask-app-5886b89967-s5sgc                  Cancelling deletion of Pod fraud-buster/flask-app-5886b89967-s5sgc
37m         Warning   FailedScheduling               pod/mongo-5dfcf95c47-mmwwg                      0/1 nodes are available: 1 Insufficient memory. no new claims to deallocate, preemption: 0/1 nodes are available: 1 No preemption victims found for incoming pod.
37m         Normal    TaintManagerEviction           pod/scheduler-6bbf94dcc-8hz2w                   Cancelling deletion of Pod fraud-buster/scheduler-6bbf94dcc-8hz2w
37m         Normal    TaintManagerEviction           pod/mongo-5cddd86795-v4s6n                      Cancelling deletion of Pod fraud-buster/mongo-5cddd86795-v4s6n
37m         Normal    TaintManagerEviction           pod/scraper-548b7ddb9f-jssgw                    Cancelling deletion of Pod fraud-buster/scraper-548b7ddb9f-jssgw
37m         Normal    TaintManagerEviction           pod/relevance-scorer-cd555d678-gww9t            Cancelling deletion of Pod fraud-buster/relevance-scorer-cd555d678-gww9t
37m         Warning   FailedScheduling               pod/review-classifier-7cdcd474d8-7rzwp          0/1 nodes are available: 1 Insufficient memory. no new claims to deallocate, preemption: 0/1 nodes are available: 1 No preemption victims found for incoming pod.
37m         Normal    TaintManagerEviction           pod/redis-6d9c5b88d4-zrwlg                      Cancelling deletion of Pod fraud-buster/redis-6d9c5b88d4-zrwlg
36m         Warning   Unhealthy                      pod/scheduler-6bbf94dcc-8hz2w                   Readiness probe failed:
36m         Normal    Pulled                         pod/scheduler-6bbf94dcc-8hz2w                   Successfully pulled image "caffeinatedkong/scheduler:latest" in 2.708s (2.708s including waiting). Image size: 487939183 bytes.
36m         Warning   FailedComputeMetricsReplicas   horizontalpodautoscaler/mongo-store-hpa         invalid metrics (1 invalid out of 1), first error is: failed to get cpu resource metric value: failed to get cpu utilization: unable to get metrics for resource cpu: unable to fetch metrics from resource metrics API: the server is currently unable to handle the request (get pods.metrics.k8s.io)
36m         Warning   FailedComputeMetricsReplicas   horizontalpodautoscaler/relevance-scorer-hpa    invalid metrics (1 invalid out of 1), first error is: failed to get cpu resource metric value: failed to get cpu utilization: unable to get metrics for resource cpu: unable to fetch metrics from resource metrics API: the server is currently unable to handle the request (get pods.metrics.k8s.io)
36m         Warning   FailedComputeMetricsReplicas   horizontalpodautoscaler/review-classifier-hpa   invalid metrics (1 invalid out of 1), first error is: failed to get cpu resource metric value: failed to get cpu utilization: unable to get metrics for resource cpu: unable to fetch metrics from resource metrics API: the server is currently unable to handle the request (get pods.metrics.k8s.io)
36m         Warning   FailedComputeMetricsReplicas   horizontalpodautoscaler/scraper-hpa             invalid metrics (1 invalid out of 1), first error is: failed to get cpu resource metric value: failed to get cpu utilization: unable to get metrics for resource cpu: unable to fetch metrics from resource metrics API: the server is currently unable to handle the request (get pods.metrics.k8s.io)
36m         Warning   FailedGetResourceMetric        horizontalpodautoscaler/mongo-store-hpa         failed to get cpu utilization: unable to get metrics for resource cpu: unable to fetch metrics from resource metrics API: the server is currently unable to handle the request (get pods.metrics.k8s.io)
36m         Warning   FailedGetResourceMetric        horizontalpodautoscaler/review-classifier-hpa   failed to get cpu utilization: unable to get metrics for resource cpu: unable to fetch metrics from resource metrics API: the server is currently unable to handle the request (get pods.metrics.k8s.io)
36m         Warning   FailedGetResourceMetric        horizontalpodautoscaler/relevance-scorer-hpa    failed to get cpu utilization: unable to get metrics for resource cpu: unable to fetch metrics from resource metrics API: the server is currently unable to handle the request (get pods.metrics.k8s.io)
36m         Warning   FailedGetResourceMetric        horizontalpodautoscaler/scraper-hpa             failed to get cpu utilization: unable to get metrics for resource cpu: unable to fetch metrics from resource metrics API: the server is currently unable to handle the request (get pods.metrics.k8s.io)
36m         Normal    SuccessfulRescale              horizontalpodautoscaler/relevance-scorer-hpa    New size: 2; reason: cpu resource utilization (percentage of request) above target
36m         Normal    Scheduled                      pod/relevance-scorer-cd555d678-6tmdr            Successfully assigned fraud-buster/relevance-scorer-cd555d678-6tmdr to minikube
36m         Normal    ScalingReplicaSet              deployment/relevance-scorer                     Scaled up replica set relevance-scorer-cd555d678 from 1 to 2
36m         Normal    SuccessfulCreate               replicaset/relevance-scorer-cd555d678           Created pod: relevance-scorer-cd555d678-6tmdr
36m         Warning   FailedCreatePodSandBox         pod/relevance-scorer-cd555d678-6tmdr            Failed to create pod sandbox: rpc error: code = Unknown desc = failed to inspect sandbox image "registry.k8s.io/pause:3.10.1": Cannot connect to the Docker daemon at unix:///var/run/docker.sock. Is the docker daemon running?
36m         Warning   FailedScheduling               pod/mongo-5dfcf95c47-mmwwg                      0/1 nodes are available: 1 node(s) had untolerated taint {node.kubernetes.io/not-ready: }. no new claims to deallocate, preemption: 0/1 nodes are available: 1 Preemption is not helpful for scheduling.
36m         Warning   FailedScheduling               pod/review-classifier-7cdcd474d8-7rzwp          0/1 nodes are available: 1 node(s) had untolerated taint {node.kubernetes.io/not-ready: }. no new claims to deallocate, preemption: 0/1 nodes are available: 1 Preemption is not helpful for scheduling.
36m         Warning   Unhealthy                      pod/scheduler-6bbf94dcc-8hz2w                   Liveness probe errored and resulted in unknown state: rpc error: code = Unknown desc = Cannot connect to the Docker daemon at unix:///var/run/docker.sock. Is the docker daemon running?
35m         Warning   Unhealthy                      pod/scheduler-6bbf94dcc-8hz2w                   Readiness probe errored and resulted in unknown state: rpc error: code = Unknown desc = Cannot connect to the Docker daemon at unix:///var/run/docker.sock. Is the docker daemon running?
35m         Warning   Unhealthy                      pod/flask-app-5886b89967-4zgfn                  Liveness probe failed: Get "http://10.244.0.127:5000/health": read tcp 10.244.0.1:43682->10.244.0.127:5000: read: connection reset by peer
35m         Warning   Unhealthy                      pod/flask-app-5886b89967-s5sgc                  Liveness probe failed: Get "http://10.244.0.130:5000/health": dial tcp 10.244.0.130:5000: connect: connection refused
35m         Warning   Unhealthy                      pod/scraper-548b7ddb9f-jssgw                    Readiness probe failed: dial tcp 10.244.0.129:50053: connect: connection refused
35m         Warning   Unhealthy                      pod/flask-app-5886b89967-4zgfn                  Liveness probe failed: Get "http://10.244.0.127:5000/health": dial tcp 10.244.0.127:5000: connect: connection refused
35m         Warning   Unhealthy                      pod/flask-app-5886b89967-s5sgc                  Readiness probe failed: Get "http://10.244.0.130:5000/health": dial tcp 10.244.0.130:5000: connect: connection refused
35m         Warning   Unhealthy                      pod/relevance-scorer-cd555d678-gww9t            Readiness probe failed: dial tcp 10.244.0.133:50052: connect: connection refused
35m         Warning   Unhealthy                      pod/mongo-store-7fb479c547-z4bjn                Readiness probe failed: dial tcp 10.244.0.126:50054: connect: connection refused
35m         Warning   Unhealthy                      pod/scraper-548b7ddb9f-jssgw                    Liveness probe failed: dial tcp 10.244.0.129:50053: connect: connection refused
35m         Warning   Unhealthy                      pod/flask-app-5886b89967-4zgfn                  Readiness probe failed: Get "http://10.244.0.127:5000/health": dial tcp 10.244.0.127:5000: connect: connection refused
35m         Warning   Unhealthy                      pod/scraper-548b7ddb9f-jssgw                    Readiness probe failed: dial tcp 10.244.0.129:50053: i/o timeout
35m         Warning   Unhealthy                      pod/scheduler-6bbf94dcc-8hz2w                   Readiness probe errored and resulted in unknown state: rpc error: code = Unknown desc = container not running (dda21608b9b6386bc49f88eba28ae71557bfaecd346fc905c9d3979916418ac9)
35m         Warning   Unhealthy                      pod/flask-app-5886b89967-s5sgc                  Readiness probe failed: Get "http://10.244.0.130:5000/health": context deadline exceeded (Client.Timeout exceeded while awaiting headers)
35m         Normal    SandboxChanged                 pod/redis-6d9c5b88d4-zrwlg                      Pod sandbox changed, it will be killed and re-created.
35m         Normal    SandboxChanged                 pod/relevance-scorer-cd555d678-gww9t            Pod sandbox changed, it will be killed and re-created.
35m         Normal    SandboxChanged                 pod/mongo-5cddd86795-v4s6n                      Pod sandbox changed, it will be killed and re-created.
35m         Normal    SandboxChanged                 pod/scraper-548b7ddb9f-jssgw                    Pod sandbox changed, it will be killed and re-created.
35m         Normal    SandboxChanged                 pod/review-classifier-85c4497458-ljdxf          Pod sandbox changed, it will be killed and re-created.
35m         Normal    SandboxChanged                 pod/mongo-store-7fb479c547-z4bjn                Pod sandbox changed, it will be killed and re-created.
35m         Normal    SandboxChanged                 pod/flask-app-5886b89967-s5sgc                  Pod sandbox changed, it will be killed and re-created.
35m         Normal    SandboxChanged                 pod/scheduler-6bbf94dcc-8hz2w                   Pod sandbox changed, it will be killed and re-created.
35m         Normal    SandboxChanged                 pod/flask-app-5886b89967-4zgfn                  Pod sandbox changed, it will be killed and re-created.
35m         Warning   Unhealthy                      pod/flask-app-5886b89967-s5sgc                  Liveness probe failed: Get "http://10.244.0.130:5000/health": context deadline exceeded (Client.Timeout exceeded while awaiting headers)
35m         Warning   Unhealthy                      pod/relevance-scorer-cd555d678-gww9t            Readiness probe failed: dial tcp 10.244.0.133:50052: i/o timeout
35m         Warning   Unhealthy                      pod/mongo-store-7fb479c547-z4bjn                Readiness probe failed: dial tcp 10.244.0.126:50054: i/o timeout
35m         Warning   Unhealthy                      pod/mongo-store-7fb479c547-z4bjn                Liveness probe failed: dial tcp 10.244.0.126:50054: i/o timeout
35m         Normal    Pulling                        pod/flask-app-5886b89967-4zgfn                  Pulling image "caffeinatedkong/flask-app:latest"
35m         Warning   Unhealthy                      pod/relevance-scorer-cd555d678-gww9t            Liveness probe failed: dial tcp 10.244.0.133:50052: i/o timeout
35m         Normal    Pulling                        pod/redis-6d9c5b88d4-zrwlg                      Pulling image "redis:latest"
35m         Normal    Pulling                        pod/scraper-548b7ddb9f-jssgw                    Pulling image "caffeinatedkong/scraper:latest"
35m         Normal    Pulling                        pod/mongo-store-7fb479c547-z4bjn                Pulling image "caffeinatedkong/mongo-store:latest"
35m         Normal    Pulled                         pod/mongo-5cddd86795-v4s6n                      Container image "mongo:7" already present on machine
35m         Normal    Created                        pod/mongo-5cddd86795-v4s6n                      Created container: mongo
35m         Normal    Pulling                        pod/scheduler-6bbf94dcc-8hz2w                   Pulling image "caffeinatedkong/scheduler:latest"
35m         Normal    Pulling                        pod/review-classifier-85c4497458-ljdxf          Pulling image "caffeinatedkong/review-classifier:latest"
35m         Normal    Pulling                        pod/flask-app-5886b89967-s5sgc                  Pulling image "caffeinatedkong/flask-app:latest"
35m         Normal    Pulled                         pod/relevance-scorer-cd555d678-6tmdr            Successfully pulled image "caffeinatedkong/relevance-scorer:latest" in 5.416s (5.416s including waiting). Image size: 898174856 bytes.
35m         Normal    Started                        pod/mongo-5cddd86795-v4s6n                      Started container mongo
35m         Normal    Pulled                         pod/flask-app-5886b89967-4zgfn                  Successfully pulled image "caffeinatedkong/flask-app:latest" in 3.314s (7.216s including waiting). Image size: 749810154 bytes.
35m         Normal    Created                        pod/flask-app-5886b89967-4zgfn                  Created container: flask-app
35m         Normal    Started                        pod/flask-app-5886b89967-4zgfn                  Started container flask-app
35m         Normal    Pulled                         pod/redis-6d9c5b88d4-zrwlg                      Successfully pulled image "redis:latest" in 4.075s (11.274s including waiting). Image size: 137229198 bytes.
35m         Normal    Created                        pod/redis-6d9c5b88d4-zrwlg                      Created container: redis
35m         Normal    Started                        pod/redis-6d9c5b88d4-zrwlg                      Started container redis
35m         Normal    Pulled                         pod/relevance-scorer-cd555d678-gww9t            Successfully pulled image "caffeinatedkong/relevance-scorer:latest" in 2.928s (14.126s including waiting). Image size: 898174856 bytes.
35m         Normal    Created                        pod/scraper-548b7ddb9f-jssgw                    Created container: scraper
35m         Normal    Pulled                         pod/scraper-548b7ddb9f-jssgw                    Successfully pulled image "caffeinatedkong/scraper:latest" in 2.957s (17.071s including waiting). Image size: 523842750 bytes.
35m         Normal    Started                        pod/scraper-548b7ddb9f-jssgw                    Started container scraper
35m         Normal    Pulled                         pod/review-classifier-85c4497458-ljdxf          Successfully pulled image "caffeinatedkong/review-classifier:latest" in 3.006s (18.088s including waiting). Image size: 1872336796 bytes.
35m         Normal    Created                        pod/review-classifier-85c4497458-ljdxf          Created container: review-classifier
35m         Normal    Started                        pod/review-classifier-85c4497458-ljdxf          Started container review-classifier
35m         Normal    Pulled                         pod/scheduler-6bbf94dcc-8hz2w                   Successfully pulled image "caffeinatedkong/scheduler:latest" in 2.985s (20.692s including waiting). Image size: 487939183 bytes.
35m         Normal    Created                        pod/scheduler-6bbf94dcc-8hz2w                   Created container: scheduler
35m         Normal    Started                        pod/scheduler-6bbf94dcc-8hz2w                   Started container scheduler
35m         Normal    Pulled                         pod/flask-app-5886b89967-s5sgc                  Successfully pulled image "caffeinatedkong/flask-app:latest" in 3.336s (23.928s including waiting). Image size: 749810154 bytes.
35m         Normal    Created                        pod/flask-app-5886b89967-s5sgc                  Created container: flask-app
35m         Warning   Unhealthy                      pod/scraper-548b7ddb9f-jssgw                    Readiness probe failed: dial tcp 10.244.0.141:50053: connect: connection refused
35m         Normal    Pulled                         pod/mongo-store-7fb479c547-z4bjn                Successfully pulled image "caffeinatedkong/mongo-store:latest" in 3.206s (27.041s including waiting). Image size: 520025736 bytes.
35m         Normal    Started                        pod/flask-app-5886b89967-s5sgc                  Started container flask-app
35m         Normal    Started                        pod/mongo-store-7fb479c547-z4bjn                Started container mongo-store
35m         Normal    Created                        pod/mongo-store-7fb479c547-z4bjn                Created container: mongo-store
34m         Warning   Unhealthy                      pod/mongo-store-7fb479c547-z4bjn                Readiness probe failed: dial tcp 10.244.0.149:50054: connect: connection refused
34m         Normal    SuccessfulCreate               replicaset/flask-app-5886b89967                 Created pod: flask-app-5886b89967-9qtnw
34m         Normal    ScalingReplicaSet              deployment/relevance-scorer                     Scaled up replica set relevance-scorer-cd555d678 from 2 to 3
34m         Normal    ScalingReplicaSet              deployment/scraper                              Scaled up replica set scraper-548b7ddb9f from 1 to 2
34m         Normal    SuccessfulCreate               replicaset/relevance-scorer-cd555d678           Created pod: relevance-scorer-cd555d678-cbbgx
34m         Normal    SuccessfulRescale              horizontalpodautoscaler/relevance-scorer-hpa    New size: 3; reason: cpu resource utilization (percentage of request) above target
34m         Normal    SuccessfulCreate               replicaset/scraper-548b7ddb9f                   Created pod: scraper-548b7ddb9f-4j7v6
34m         Normal    SuccessfulRescale              horizontalpodautoscaler/scraper-hpa             New size: 2; reason: cpu resource utilization (percentage of request) above target
34m         Normal    Killing                        pod/relevance-scorer-cd555d678-gww9t            Container relevance-scorer failed liveness probe, will be restarted
34m         Normal    ScalingReplicaSet              deployment/relevance-scorer                     Scaled down replica set relevance-scorer-cd555d678 from 3 to 1
34m         Warning   Unhealthy                      pod/relevance-scorer-cd555d678-gww9t            Liveness probe failed: dial tcp 10.244.0.140:50052: connect: connection refused
34m         Normal    SuccessfulDelete               replicaset/relevance-scorer-cd555d678           Deleted pod: relevance-scorer-cd555d678-gww9t
34m         Normal    SuccessfulDelete               replicaset/relevance-scorer-cd555d678           Deleted pod: relevance-scorer-cd555d678-cbbgx
34m         Normal    SuccessfulDelete               replicaset/scraper-548b7ddb9f                   Deleted pod: scraper-548b7ddb9f-4j7v6
34m         Normal    ScalingReplicaSet              deployment/scraper                              Scaled down replica set scraper-548b7ddb9f from 2 to 1
34m         Normal    SuccessfulDelete               replicaset/flask-app-5886b89967                 Deleted pod: flask-app-5886b89967-9qtnw
34m         Warning   Unhealthy                      pod/relevance-scorer-cd555d678-6tmdr            Liveness probe failed: dial tcp 10.244.0.138:50052: connect: connection refused
34m         Normal    Killing                        pod/relevance-scorer-cd555d678-6tmdr            Container relevance-scorer failed liveness probe, will be restarted
34m         Normal    ScalingReplicaSet              deployment/flask-app                            Scaled up replica set flask-app-5886b89967 from 2 to 3
34m         Normal    SuccessfulRescale              horizontalpodautoscaler/flask-app-hpa           New size: 3; reason: cpu resource utilization (percentage of request) above target
34m         Normal    SuccessfulCreate               replicaset/flask-app-5886b89967                 Created pod: flask-app-5886b89967-g67j6
34m         Warning   FailedGetResourceMetric        horizontalpodautoscaler/mongo-store-hpa         failed to get cpu utilization: unable to get metrics for resource cpu: no metrics returned from resource metrics API
34m         Warning   FailedComputeMetricsReplicas   horizontalpodautoscaler/mongo-store-hpa         invalid metrics (1 invalid out of 1), first error is: failed to get cpu resource metric value: failed to get cpu utilization: unable to get metrics for resource cpu: no metrics returned from resource metrics API
34m         Normal    Pulling                        pod/relevance-scorer-cd555d678-gww9t            Pulling image "caffeinatedkong/relevance-scorer:latest"
34m         Normal    Pulled                         pod/relevance-scorer-cd555d678-gww9t            Successfully pulled image "caffeinatedkong/relevance-scorer:latest" in 2.639s (2.639s including waiting). Image size: 898174856 bytes.
34m         Normal    Created                        pod/relevance-scorer-cd555d678-gww9t            Created container: relevance-scorer
34m         Normal    Started                        pod/relevance-scorer-cd555d678-gww9t            Started container relevance-scorer
34m         Normal    Killing                        pod/relevance-scorer-cd555d678-gww9t            Stopping container relevance-scorer
34m         Normal    Pulling                        pod/relevance-scorer-cd555d678-6tmdr            Pulling image "caffeinatedkong/relevance-scorer:latest"
34m         Normal    Sync                           ingress/fraud-buster-ingress                    Scheduled for sync
34m         Normal    Created                        pod/relevance-scorer-cd555d678-6tmdr            Created container: relevance-scorer
34m         Normal    Pulled                         pod/relevance-scorer-cd555d678-6tmdr            Successfully pulled image "caffeinatedkong/relevance-scorer:latest" in 2.449s (2.449s including waiting). Image size: 898174856 bytes.
34m         Normal    Started                        pod/relevance-scorer-cd555d678-6tmdr            Started container relevance-scorer
33m         Warning   Unhealthy                      pod/relevance-scorer-cd555d678-gww9t            Readiness probe failed: dial tcp 10.244.0.140:50052: connect: connection refused
33m         Warning   Unhealthy                      pod/relevance-scorer-cd555d678-6tmdr            Readiness probe failed: dial tcp 10.244.0.138:50052: connect: connection refused
33m         Normal    Pulling                        pod/flask-app-5886b89967-g67j6                  Pulling image "caffeinatedkong/flask-app:latest"
33m         Normal    Pulled                         pod/flask-app-5886b89967-g67j6                  Successfully pulled image "caffeinatedkong/flask-app:latest" in 2.494s (2.494s including waiting). Image size: 749810154 bytes.
33m         Normal    Started                        pod/flask-app-5886b89967-g67j6                  Started container flask-app
33m         Normal    Created                        pod/flask-app-5886b89967-g67j6                  Created container: flask-app
33m         Warning   FailedGetResourceMetric        horizontalpodautoscaler/relevance-scorer-hpa    failed to get cpu utilization: unable to get metrics for resource cpu: no metrics returned from resource metrics API
33m         Warning   FailedComputeMetricsReplicas   horizontalpodautoscaler/relevance-scorer-hpa    invalid metrics (1 invalid out of 1), first error is: failed to get cpu resource metric value: failed to get cpu utilization: unable to get metrics for resource cpu: no metrics returned from resource metrics API
32m         Warning   FailedComputeMetricsReplicas   horizontalpodautoscaler/relevance-scorer-hpa    invalid metrics (1 invalid out of 1), first error is: failed to get cpu resource metric value: failed to get cpu utilization: did not receive metrics for targeted pods (pods might be unready)
32m         Warning   FailedGetResourceMetric        horizontalpodautoscaler/relevance-scorer-hpa    failed to get cpu utilization: did not receive metrics for targeted pods (pods might be unready)
31m         Normal    Killing                        pod/flask-app-5886b89967-g67j6                  Stopping container flask-app
31m         Normal    ScalingReplicaSet              deployment/flask-app                            Scaled down replica set flask-app-5886b89967 from 3 to 2
31m         Normal    SuccessfulRescale              horizontalpodautoscaler/flask-app-hpa           New size: 2; reason: All metrics below target
31m         Normal    SuccessfulDelete               replicaset/flask-app-5886b89967                 Deleted pod: flask-app-5886b89967-g67j6
4m55s       Normal    SuccessfulCreate               replicaset/flask-app-5886b89967                 Created pod: flask-app-5886b89967-m48x2
4m55s       Normal    ScalingReplicaSet              deployment/mongo-store                          Scaled up replica set mongo-store-7fb479c547 from 1 to 2
4m55s       Normal    SuccessfulCreate               replicaset/flask-app-5886b89967                 Created pod: flask-app-5886b89967-gs9rc
4m55s       Normal    ScalingReplicaSet              deployment/flask-app                            Scaled up replica set flask-app-5886b89967 from 2 to 4
4m55s       Normal    SuccessfulRescale              horizontalpodautoscaler/mongo-store-hpa         New size: 2; reason: cpu resource utilization (percentage of request) above target
4m55s       Normal    SuccessfulRescale              horizontalpodautoscaler/flask-app-hpa           New size: 4; reason: cpu resource utilization (percentage of request) above target
4m55s       Normal    SuccessfulCreate               replicaset/mongo-store-7fb479c547               Created pod: mongo-store-7fb479c547-4t94z
4m51s       Normal    Pulling                        pod/flask-app-5886b89967-gs9rc                  Pulling image "caffeinatedkong/flask-app:latest"
4m48s       Normal    Created                        pod/flask-app-5886b89967-gs9rc                  Created container: flask-app
4m48s       Normal    Pulled                         pod/flask-app-5886b89967-gs9rc                  Successfully pulled image "caffeinatedkong/flask-app:latest" in 2.914s (2.914s including waiting). Image size: 749810154 bytes.
4m47s       Normal    Started                        pod/flask-app-5886b89967-gs9rc                  Started container flask-app
4m25s       Normal    SuccessfulCreate               replicaset/flask-app-5886b89967                 Created pod: flask-app-5886b89967-zz5lt
4m25s       Normal    SuccessfulCreate               replicaset/flask-app-5886b89967                 Created pod: flask-app-5886b89967-kc2nn
4m25s       Normal    SuccessfulCreate               replicaset/flask-app-5886b89967                 Created pod: flask-app-5886b89967-vdv68
4m25s       Normal    SuccessfulCreate               replicaset/flask-app-5886b89967                 Created pod: flask-app-5886b89967-vsfhc
4m25s       Normal    SuccessfulRescale              horizontalpodautoscaler/flask-app-hpa           New size: 8; reason: cpu resource utilization (percentage of request) above target
4m25s       Normal    ScalingReplicaSet              deployment/flask-app                            Scaled up replica set flask-app-5886b89967 from 4 to 8
2m55s       Normal    SuccessfulCreate               replicaset/mongo-store-7fb479c547               Created pod: mongo-store-7fb479c547-gtm82
2m55s       Normal    SuccessfulRescale              horizontalpodautoscaler/mongo-store-hpa         New size: 3; reason: cpu resource utilization (percentage of request) above target
2m55s       Normal    ScalingReplicaSet              deployment/mongo-store                          Scaled up replica set mongo-store-7fb479c547 from 2 to 3
